<?xml version='1.0'?>
<sdf version='1.7'>
  <model name='spherical_wrist'>
    <link name='gantry_base'>
      <pose>0 0 0.025 0 -0 0</pose>
      <gravity>1</gravity>
      <inertial>
        <mass>1</mass>
        <inertia>
          <ixx>0.125</ixx>
          <ixy>0</ixy>
          <ixz>0</ixz>
          <iyy>0.125</iyy>
          <iyz>0</iyz>
          <izz>0.125</izz>
        </inertia>
        <pose>0 0 0 0 -0 0</pose>
      </inertial>
      <visual name='visual'>
        <pose>0 0 0.025 0 -0 0</pose>
        <geometry>
          <box>
            <size>0.05 0.05 0.05</size>
          </box>
        </geometry>
      </visual>
      <collision name='collision'>
        <laser_retro>0</laser_retro>
        <max_contacts>10</max_contacts>
        <pose>0 0 0.025 0 -0 0</pose>
        <geometry>
          <box>
            <size>0.05 0.05 0.05</size>
          </box>
        </geometry>
      </collision>
    </link>
    <link name='servo1'>
      <pose>0 0 0 3.141593 -0 0</pose>
      <gravity>1</gravity>
      <inertial>
        <mass>0.1</mass>
        <inertia>
          <ixx>0.145833</ixx>
          <ixy>0</ixy>
          <ixz>0</ixz>
          <iyy>0.145833</iyy>
          <iyz>0</iyz>
          <izz>0.125</izz>
        </inertia>
        <pose>0 0 0 0 -0 0</pose>
      </inertial>
      <visual name='visual'>
        <pose>0 0 0 0 -0 0</pose>
        <geometry>
          <cylinder>
            <radius>0.02</radius>
            <length>0.05</length>
          </cylinder>
        </geometry>
      </visual>
      <collision name='collision'>
        <laser_retro>0</laser_retro>
        <max_contacts>10</max_contacts>
        <pose>0 0 0 0 -0 0</pose>
        <geometry>
          <cylinder>
            <radius>0.02</radius>
            <length>0.05</length>
          </cylinder>
        </geometry>
      </collision>
    </link>
    <link name='servo2'>
      <pose>0 0 -0.075 -1.5707 -0 0</pose>
      <gravity>1</gravity>
      <inertial>
        <mass>0.1</mass>
        <inertia>
          <ixx>0.145833</ixx>
          <ixy>0</ixy>
          <ixz>0</ixz>
          <iyy>0.145833</iyy>
          <iyz>0</iyz>
          <izz>0.125</izz>
        </inertia>
        <pose>0 0 0 0 -0 0</pose>
      </inertial>
      <visual name='visual'>
        <pose>0 0 0 0 -0 0</pose>
        <geometry>
          <cylinder>
            <radius>0.02</radius>
            <length>0.05</length>
          </cylinder>
        </geometry>
      </visual>
      <collision name='collision'>
        <laser_retro>0</laser_retro>
        <max_contacts>10</max_contacts>
        <pose>0 0 0 0 -0 0</pose>
        <geometry>
          <cylinder>
            <radius>0.02</radius>
            <length>0.05</length>
          </cylinder>
        </geometry>
      </collision>
    </link>
    <link name='servo2_rotor'>
      <pose>0 0 -0.075 -1.5707 -0 0</pose>
      <gravity>1</gravity>
      <inertial>
        <mass>0.1</mass>
        <inertia>
          <ixx>0.145833</ixx>
          <ixy>0</ixy>
          <ixz>0</ixz>
          <iyy>0.145833</iyy>
          <iyz>0</iyz>
          <izz>0.125</izz>
        </inertia>
        <pose>0 0 0 0 -0 0</pose>
      </inertial>
      <visual name='visual'>
        <pose>0 0 0 0 -0 0</pose>
        <geometry>
          <cylinder>
            <radius>0.01</radius>
            <length>0.05</length>
          </cylinder>
        </geometry>
      </visual>
      <collision name='collision'>
        <laser_retro>0</laser_retro>
        <max_contacts>10</max_contacts>
        <pose>0 0 0 0 -0 0</pose>
        <geometry>
          <cylinder>
            <radius>0.01</radius>
            <length>0.05</length>
          </cylinder>
        </geometry>
      </collision>
    </link>
    <link name='servo3'>
      <pose>0 0 -0.15 3.141593 -0 0</pose>
      <gravity>1</gravity>
      <inertial>
        <mass>0.1</mass>
        <inertia>
          <ixx>0.145833</ixx>
          <ixy>0</ixy>
          <ixz>0</ixz>
          <iyy>0.145833</iyy>
          <iyz>0</iyz>
          <izz>0.125</izz>
        </inertia>
        <pose>0 0 0 0 -0 0</pose>
      </inertial>
      <visual name='visual'>
        <pose>0 0 0 0 -0 0</pose>
        <geometry>
          <cylinder>
            <radius>0.02</radius>
            <length>0.05</length>
          </cylinder>
        </geometry>
      </visual>
      <collision name='collision'>
        <laser_retro>0</laser_retro>
        <max_contacts>10</max_contacts>
        <pose>0 0 0 0 -0 0</pose>
        <geometry>
          <cylinder>
            <radius>0.02</radius>
            <length>0.05</length>
          </cylinder>
        </geometry>
      </collision>
    </link>
    <link name='link1'>
      <pose>0 0 -0.04 3.141593 -0 0</pose>
      <gravity>1</gravity>
      <inertial>
        <mass>0.01</mass>
        <inertia>
          <ixx>0.145833</ixx>
          <ixy>0</ixy>
          <ixz>0</ixz>
          <iyy>0.145833</iyy>
          <iyz>0</iyz>
          <izz>0.125</izz>
        </inertia>
        <pose>0 0 0 0 -0 0</pose>
      </inertial>
      <visual name='visual'>
        <pose>0 0 0 0 -0 0</pose>
        <geometry>
          <cylinder>
            <radius>0.01</radius>
            <length>0.03</length>
          </cylinder>
        </geometry>
      </visual>
      <collision name='collision'>
        <laser_retro>0</laser_retro>
        <max_contacts>10</max_contacts>
        <pose>0 0 0 0 -0 0</pose>
        <geometry>
          <cylinder>
            <radius>0.01</radius>
            <length>0.03</length>
          </cylinder>
        </geometry>
      </collision>
    </link>
    <link name='link2'>
      <pose>0 0 -0.11 3.141593 -0 0</pose>
      <gravity>1</gravity>
      <inertial>
        <mass>0.01</mass>
        <inertia>
          <ixx>0.145833</ixx>
          <ixy>0</ixy>
          <ixz>0</ixz>
          <iyy>0.145833</iyy>
          <iyz>0</iyz>
          <izz>0.125</izz>
        </inertia>
        <pose>0 0 0 0 -0 0</pose>
      </inertial>
      <visual name='visual'>
        <pose>0 0 0 0 -0 0</pose>
        <geometry>
          <cylinder>
            <radius>0.01</radius>
            <length>0.03</length>
          </cylinder>
        </geometry>
      </visual>
      <collision name='collision'>
        <laser_retro>0</laser_retro>
        <max_contacts>10</max_contacts>
        <pose>0 0 0 0 -0 0</pose>
        <geometry>
          <cylinder>
            <radius>0.01</radius>
            <length>0.03</length>
          </cylinder>
        </geometry>
      </collision>
    </link>
    <link name='link3'>
      <pose>0 0 -0.19 3.141593 -0 0</pose>
      <gravity>1</gravity>
      <inertial>
        <mass>0.01</mass>
        <inertia>
          <ixx>0.145833</ixx>
          <ixy>0</ixy>
          <ixz>0</ixz>
          <iyy>0.145833</iyy>
          <iyz>0</iyz>
          <izz>0.125</izz>
        </inertia>
        <pose>0 0 0 0 -0 0</pose>
      </inertial>
      <visual name='visual'>
        <pose>0 0 0 0 -0 0</pose>
        <geometry>
          <cylinder>
            <radius>0.01</radius>
            <length>0.03</length>
          </cylinder>
        </geometry>
      </visual>
      <collision name='collision'>
        <laser_retro>0</laser_retro>
        <max_contacts>10</max_contacts>
        <pose>0 0 0 0 -0 0</pose>
        <geometry>
          <cylinder>
            <radius>0.01</radius>
            <length>0.03</length>
          </cylinder>
        </geometry>
      </collision>
    </link>
    <link name='tweezers'>
      <pose>0 0 -0.2325 3.141593 -0 0</pose>
      <gravity>1</gravity>
      <inertial>
        <mass>0.01</mass>
        <inertia>
          <ixx>0.125</ixx>
          <ixy>0</ixy>
          <ixz>0</ixz>
          <iyy>0.125</iyy>
          <iyz>0</iyz>
          <izz>0.125</izz>
        </inertia>
        <pose>0 0 0 0 -0 0</pose>
      </inertial>
      <visual name='visual'>
        <pose>0 0 0 0 -0 0</pose>
        <geometry>
          <box>
            <size>0.02 0.02 0.075</size>
          </box>
        </geometry>
      </visual>
      <collision name='collision'>
        <laser_retro>0</laser_retro>
        <max_contacts>10</max_contacts>
        <pose>0 0 0 0 -0 0</pose>
        <geometry>
          <box>
            <size>0.05 0.02 0.075</size>
          </box>
        </geometry>
      </collision>
    </link>
    <joint name='theta1' type='revolute'>
      <parent>servo1</parent>
      <child>link1</child>
      <axis>
        <xyz>0 0 1</xyz>
        <limit>
          <lower>-3.1415</lower>
          <upper>3.1415</upper>
          <effort>100</effort>
          <velocity>100</velocity>
        </limit>
      </axis>
    </joint>
    <joint name='theta2' type='revolute'>
      <parent>servo2</parent>
      <child>servo2_rotor</child>
      <axis>
        <xyz>0 0 1</xyz>
        <limit>
          <lower>-3.1415</lower>
          <upper>3.1415</upper>
          <effort>100</effort>
          <velocity>100</velocity>
        </limit>
      </axis>
    </joint>
    <joint name='theta3' type='revolute'>
      <parent>servo3</parent>
      <child>link3</child>
      <axis>
        <xyz>0 0 1</xyz>
        <limit>
          <lower>-3.1415</lower>
          <upper>3.1415</upper>
          <effort>100</effort>
          <velocity>100</velocity>
        </limit>
      </axis>
    </joint>
    <joint name='servo2_joint' type='fixed'>
      <parent>link1</parent>
      <child>servo2</child>
    </joint>
    <joint name='servo3_joint' type='fixed'>
      <parent>link2</parent>
      <child>servo3</child>
    </joint>
    <joint name='servo2_rotor_joint' type='fixed'>
      <parent>servo2_rotor</parent>
      <child>link2</child>
    </joint>
    <joint name='tweezer_joint' type='fixed'>
      <parent>link3</parent>
      <child>tweezers</child>
    </joint>
    <joint name='base_joint' type='fixed'>
      <parent>gantry_base</parent>
      <child>servo1</child>
    </joint>
  </model>
</sdf>
